Workbook

Sheet Guide
A1: OBP*SLG = | B1: OTS | G1: Starting pitcher projected ERA * projected innings in game | M1: projected ERA from season performance and projections (Season ERA, Season xERA, Season FIP ERA, Season XFIP ERA)
A2: *Remove non-starters | G2: add bullpen projected ERA * innings
A3: *Divide by AL/NL average OTS | G3: divide by league average ERA
A4: ZiPS projected OTS
A5: Choose OTS, adjus for RHP/LHP diff and ballpark | K5: Home offensive rating (i.e. 1.07 for 107%/7% better) * pitching rating (expected runs given up as % of league average i.e. 4.1 RAA = 97% average = .97)
K7: win percentage = (runs ^exp) /(RA*exp)+(runs^exp) | Q7: exp based on game total table
A9: Dodgers (Bauer) @ | C9: Astros (Garcia) | E9: 8.5 | F9: Indians (Mackenzie) @ | H9: Tigers (Urena) | I9: 10 | K9: =POWER(4.64,1.916)/((POWER(4.64,1.916)+POWER(4.32,1.916))
A10: =1.384*1.0677*4.4 -> 6.5018659 | B10: xRuns | C10: =1.0677*0.923*4.4 -> 4.3361432 | F10: =1.167*0.96*4.38 -> 4.9070016 | H10: =1.21*0.939*4.38 -> 4.9765122
A11: =POWER(6.5,1.84)/(POWER(6.5,1.84)+(POWER(4.336,1.84))) -> 0.67807162 | C11: -212 | F11: =POWER(F10,1.95)/(POWER(F10,1.95)+(POWER(H10,1.95))) -> 0.49314316 | K11: =POWER(4.64,1.916)/(POWER(4.64,1.916)+(POWER(4.32,1.916))) -> 0.53417547 | L11: WIN% | M11: 3.5% standard home field adjustment | R11: League average ERA currently = 4.05
A12: Win% | C12: Odds | R12: 4.36 | S12: runs/game
A13: Padres (Paddack) @ | C13: Brewers (Lauer) | E13: 8 | F13: Blue Jays (Manoah) @ | H13: Yankees (German) | I13: 9.5 | K13: add .5 total runs to your # if >90 deg, subtract .5 if <55 deg
A14: =1.406*1.106*4.4 -> 6.8421584 | C14: =1.123*0.941935484*4.4 -> 4.6542916 | K14: cold weather = power pitcher > finesse
A15: =POWER(A14,1.8)/(POWER(A14,1.8)+(POWER(C14,1.8))) -> 0.66675936 | C15: -200 | K15: watch wind speed for finesse pitchers
K16: interleague game diff?
A17: Giants (Cueto) @ | C17: Diamondbacks (Merrill Kelly) | E17: 8.5 | F17: Reds (Hoffman) @ | H17: Nationals (Ross) | J17: 9.5
A18: =1.01*1.546*4.4 -> 6.870424 | C18: =1.227*0.98*4.4 -> 5.290824 | F18: =1.218*1.0645*4.38 -> 5.6789372 | H18: =1.201*1.029*4.38 -> 5.412931 | K18: https://www.fangraphs.com/leaders.aspx?pos=all&stats=rel&lg=all&qual=0&type=3&season=2021&month=0&season1=2021&ind=0&team=0,ts&rost=0&age=0&filter=&players=0&startdate=2021-01-01&enddate=2021-12-31
A19: =POWER(A18,1.84)/(POWER(A18,1.84)+(POWER(C18,1.84))) -> 0.61791395 | C19: -163 | F19: =POWER(F18,1.92)/(POWER(F18,1.92)+(POWER(H18,1.92))) -> 0.52301095 | H19: -109 | K19: https://baseballsavant.mlb.com/leaderboard/expected_statistics?type=pitcher&year=2021&position=&team=&min=25
K20: https://www.baseball-reference.com/leagues/MLB/pitch.shtml
A21: Braves (Smyly) @ | C21: Red Sox (Pivetta) | E21: 10.5 | F21: Cubs (T Williams) @ | H21: Pirates (Crowe) | J21: 8.5
A22: =0.927*1.06*4.38 -> 4.3038756 | C22: =1.27*1.077*4.38 -> 5.9909202 | F22: =1.019*1.162*4.38 -> 5.1862616 | H22: =0.93*1.103*4.38 -> 4.4929602 | K22: Total | L22: Exponent | M22: Total2 | N22: Exponent2
A23: =POWER(A22,1.98)/(POWER(A22,1.98)+(POWER(C22,1.98))) -> 0.34189887 | C23: -163 | F23: =POWER(F22,1.84)/(POWER(F22,1.84)+(POWER(H22,1.84))) -> 0.56562977 | H23: -130 | K23: 6.5 | L23: 1.67 | M23: 10 | N23: 1.95
K24: 7 | L24: 1.72 | M24: 10.5 | N24: 1.98
A25: Royals (Minor) @ | C25: Rays (Glasnow) | E25: 7 | F25: Rangers (Dunning) @ | H25: Angels (Canning) | J25: 8.5 | K25: 7.5 | L25: 1.76 | M25: 11 | N25: 2.01
A26: =0.788*0.9612*4.38 -> 3.3175241 | C26: =1.091*1.02*4.38 -> 4.8741516 | F26: =1.223*0.984*4.38 -> 5.2710322 | H26: =0.878*0.99*4.38 -> 3.8071836 | K26: 8 | L26: 1.8 | M26: 11.5 | N26: 2.04
A27: =POWER(A26,1.72)/(POWER(A26,1.72)+(POWER(C26,1.72))) -> 0.34035088 | C27: -185 | F27: =POWER(F26,1.84)/(POWER(F26,1.84)+(POWER(H26,1.84))) -> 0.64534033 | H27: -177 | K27: 8.5 | L27: 1.84 | M27: 12 | N27: 2.07
K28: 9 | L28: 1.88 | M28: 12.5 | N28: 2.1
A29: Rockies (Marquez) @ | C29: Mets (Stroman) | E29: 6.5 | F29: Cardinals (Gant) @ | H29: White Sox (Rodon) | J29: 8.5 | K29: 9.5 | L29: 1.92 | M29: 13 | N29: 2.12
A30: =0.8423*0.96*4.38 -> 3.541703 | C30: =1.154*0.9*4.38 -> 4.549068 | F30: =0.637*0.98*4.38 -> 2.7342588 | H30: =1.02*1.054*4.38 -> 4.7088504
A31: =POWER(A30,1.67)/(POWER(A30,1.67)+(POWER(C30,1.67))) -> 0.39698932 | C31: -122 | F31: =POWER(F30,1.84)/(POWER(F30,1.84)+(POWER(H30,1.84))) -> 0.26890338 | H31: -230 | L31: Running total:
L32: W | M32: L
F33: Orioles (J Lopez) @ | H33: Twins (Pineda) | I33: 9 | L33: 1
F34: =1.02*0.96*4.38 -> 4.288896 | H34: =1.18*1.04*4.38 -> 5.375136
F35: =POWER(F34,1.88)/(POWER(F34,1.88)+(POWER(H34,1.88))) -> 0.39545993 | H35: -150

Sheet Model
A1: Marlins | B1: Teams | C1: Pirates | D1: Game Total | E1: Red Sox | F1: Teams | G1: Yankees | H1: Game Total | I1: Nationals | J1: Teams | K1: Phillies | L1: Game Total | O1: Value of the Day | P1: Odds | Q1: EV
A2: =IF(A1="Diamondbacks",('Offensive Values'!$P$2+'Offensive Values'!$Q$2)/2,IF(A1="Braves",('Offensive Values'!$P$3+'Offensive Values'!$Q$3)/2,IF(A1="Orioles",('Offensive Values'!$P$4+'Offensive Values'!$Q$4)/2,IF(A1="Red Sox",('Offensive Values'!$P$5+'Offensive Values'!$Q$5)/2,IF(A1="Cubs",('Offensive Values'!$P$6+'Offensive Values'!$Q$6)/2,IF(A1="White Sox",('Offensive Values'!$P$7+'Offensive Values'!$Q$7)/2,IF(A1="Reds",('Offensive Values'!$P$8+'Offensive Values'!$Q$8)/2,IF(A1="Indians",('Offensive Values'!$P$9+'Offensive Values'!$Q$9)/2,IF(A1="Rockies",('Offensive Values'!$P$10+'Offensive Values'!$Q$10)/2,IF(A1="Tigers",('Offensive Values'!$P$11+'Offensive Values'!$Q$11)/2,IF(A1="Astros",('Offensive Values'!$P$12+'Offensive Values'!$Q$12)/2,IF(A1="Royals",('Offensive Values'!$P$13+'Offensive Values'!$Q$13)/2,IF(A1="Angels",('Offensive Values'!$P$14+'Offensive Values'!$Q$14)/2,IF(A1="Dodgers",('Offensive Values'!$P$15+'Offensive Values'!$Q$15)/2,IF(A1="Marlins",('Offensive Values'!$P$16+'Offensive Values'!$Q$16)/2,IF(A1="Brewers",('Offensive Values'!$P$17+'Offensive Values'!$Q$17)/2,IF(A1="Twins",('Offensive Values'!$P$18+'Offensive Values'!$Q$18)/2,IF(A1="Mets",('Offensive Values'!$P$19+'Offensive Values'!$Q$19)/2,IF(A1="Yankees",('Offensive Values'!$P$20+'Offensive Values'!$Q$20)/2,IF(A1="Athletics",('Offensive Values'!$P$21+'Offensive Values'!$Q$21)/2,IF(A1="Phillies",('Offensive Values'!$P$22+'Offensive Values'!$Q$22)/2,IF(A1="Pirates",('Offensive Values'!$P$23+'Offensive Values'!$Q$23)/2,IF(A1="Padres",('Offensive Values'!$P$24+'Offensive Values'!$Q$24)/2,IF(A1="Giants",('Offensive Values'!$P$25+'Offensive Values'!$Q$25)/2,IF(A1="Mariners",('Offensive Values'!$P$26+'Offensive Values'!$Q$26)/2,IF(A1="Cardinals",('Offensive Values'!$P$27+'Offensive Values'!$Q$27)/2,IF(A1="Rays",('Offensive Values'!$P$28+'Offensive Values'!$Q$28)/2,IF(A1="Rangers",('Offensive Values'!$P$29+'Offensive Values'!$Q$29)/2,IF(A1="Blue Jays",('Offensive Values'!$P$30+'Offensive Values'!$Q$30)/2,IF(A1="Nationals",('Offensive Values'!$P$31+'Offensive Values'!$Q$31)/2)))))))))))))))))))))))))))))) -> 0.93178279 | B2: Offensive Value | C2: =IF(C1="Diamondbacks",('Offensive Values'!$P$2+'Offensive Values'!$Q$2)/2,IF(C1="Braves",('Offensive Values'!$P$3+'Offensive Values'!$Q$3)/2,IF(C1="Orioles",('Offensive Values'!$P$4+'Offensive Values'!$Q$4)/2,IF(C1="Red Sox",('Offensive Values'!$P$5+'Offensive Values'!$Q$5)/2,IF(C1="Cubs",('Offensive Values'!$P$6+'Offensive Values'!$Q$6)/2,IF(C1="White Sox",('Offensive Values'!$P$7+'Offensive Values'!$Q$7)/2,IF(C1="Reds",('Offensive Values'!$P$8+'Offensive Values'!$Q$8)/2,IF(C1="Indians",('Offensive Values'!$P$9+'Offensive Values'!$Q$9)/2,IF(C1="Rockies",('Offensive Values'!$P$10+'Offensive Values'!$Q$10)/2,IF(C1="Tigers",('Offensive Values'!$P$11+'Offensive Values'!$Q$11)/2,IF(C1="Astros",('Offensive Values'!$P$12+'Offensive Values'!$Q$12)/2,IF(C1="Royals",('Offensive Values'!$P$13+'Offensive Values'!$Q$13)/2,IF(C1="Angels",('Offensive Values'!$P$14+'Offensive Values'!$Q$14)/2,IF(C1="Dodgers",('Offensive Values'!$P$15+'Offensive Values'!$Q$15)/2,IF(C1="Marlins",('Offensive Values'!$P$16+'Offensive Values'!$Q$16)/2,IF(C1="Brewers",('Offensive Values'!$P$17+'Offensive Values'!$Q$17)/2,IF(C1="Twins",('Offensive Values'!$P$18+'Offensive Values'!$Q$18)/2,IF(C1="Mets",('Offensive Values'!$P$19+'Offensive Values'!$Q$19)/2,IF(C1="Yankees",('Offensive Values'!$P$20+'Offensive Values'!$Q$20)/2,IF(C1="Athletics",('Offensive Values'!$P$21+'Offensive Values'!$Q$21)/2,IF(C1="Phillies",('Offensive Values'!$P$22+'Offensive Values'!$Q$22)/2,IF(C1="Pirates",('Offensive Values'!$P$23+'Offensive Values'!$Q$23)/2,IF(C1="Padres",('Offensive Values'!$P$24+'Offensive Values'!$Q$24)/2,IF(C1="Giants",('Offensive Values'!$P$25+'Offensive Values'!$Q$25)/2,IF(C1="Mariners",('Offensive Values'!$P$26+'Offensive Values'!$Q$26)/2,IF(C1="Cardinals",('Offensive Values'!$P$27+'Offensive Values'!$Q$27)/2,IF(C1="Rays",('Offensive Values'!$P$28+'Offensive Values'!$Q$28)/2,IF(C1="Rangers",('Offensive Values'!$P$29+'Offensive Values'!$Q$29)/2,IF(C1="Blue Jays",('Offensive Values'!$P$30+'Offensive Values'!$Q$30)/2,IF(C1="Nationals",('Offensive Values'!$P$31+'Offensive Values'!$Q$31)/2)))))))))))))))))))))))))))))) -> 0.93160077 | D2: 8 | E2: =IF(E1="Diamondbacks",('Offensive Values'!$P$2+'Offensive Values'!$Q$2)/2,IF(E1="Braves",('Offensive Values'!$P$3+'Offensive Values'!$Q$3)/2,IF(E1="Orioles",('Offensive Values'!$P$4+'Offensive Values'!$Q$4)/2,IF(E1="Red Sox",('Offensive Values'!$P$5+'Offensive Values'!$Q$5)/2,IF(E1="Cubs",('Offensive Values'!$P$6+'Offensive Values'!$Q$6)/2,IF(E1="White Sox",('Offensive Values'!$P$7+'Offensive Values'!$Q$7)/2,IF(E1="Reds",('Offensive Values'!$P$8+'Offensive Values'!$Q$8)/2,IF(E1="Indians",('Offensive Values'!$P$9+'Offensive Values'!$Q$9)/2,IF(E1="Rockies",('Offensive Values'!$P$10+'Offensive Values'!$Q$10)/2,IF(E1="Tigers",('Offensive Values'!$P$11+'Offensive Values'!$Q$11)/2,IF(E1="Astros",('Offensive Values'!$P$12+'Offensive Values'!$Q$12)/2,IF(E1="Royals",('Offensive Values'!$P$13+'Offensive Values'!$Q$13)/2,IF(E1="Angels",('Offensive Values'!$P$14+'Offensive Values'!$Q$14)/2,IF(E1="Dodgers",('Offensive Values'!$P$15+'Offensive Values'!$Q$15)/2,IF(E1="Marlins",('Offensive Values'!$P$16+'Offensive Values'!$Q$16)/2,IF(E1="Brewers",('Offensive Values'!$P$17+'Offensive Values'!$Q$17)/2,IF(E1="Twins",('Offensive Values'!$P$18+'Offensive Values'!$Q$18)/2,IF(E1="Mets",('Offensive Values'!$P$19+'Offensive Values'!$Q$19)/2,IF(E1="Yankees",('Offensive Values'!$P$20+'Offensive Values'!$Q$20)/2,IF(E1="Athletics",('Offensive Values'!$P$21+'Offensive Values'!$Q$21)/2,IF(E1="Phillies",('Offensive Values'!$P$22+'Offensive Values'!$Q$22)/2,IF(E1="Pirates",('Offensive Values'!$P$23+'Offensive Values'!$Q$23)/2,IF(E1="Padres",('Offensive Values'!$P$24+'Offensive Values'!$Q$24)/2,IF(E1="Giants",('Offensive Values'!$P$25+'Offensive Values'!$Q$25)/2,IF(E1="Mariners",('Offensive Values'!$P$26+'Offensive Values'!$Q$26)/2,IF(E1="Cardinals",('Offensive Values'!$P$27+'Offensive Values'!$Q$27)/2,IF(E1="Rays",('Offensive Values'!$P$28+'Offensive Values'!$Q$28)/2,IF(E1="Rangers",('Offensive Values'!$P$29+'Offensive Values'!$Q$29)/2,IF(E1="Blue Jays",('Offensive Values'!$P$30+'Offensive Values'!$Q$30)/2,IF(E1="Nationals",('Offensive Values'!$P$31+'Offensive Values'!$Q$31)/2)))))))))))))))))))))))))))))) -> 1.0446152 | F2: Offensive Value | G2: =IF(G1="Diamondbacks",('Offensive Values'!$P$2+'Offensive Values'!$Q$2)/2,IF(G1="Braves",('Offensive Values'!$P$3+'Offensive Values'!$Q$3)/2,IF(G1="Orioles",('Offensive Values'!$P$4+'Offensive Values'!$Q$4)/2,IF(G1="Red Sox",('Offensive Values'!$P$5+'Offensive Values'!$Q$5)/2,IF(G1="Cubs",('Offensive Values'!$P$6+'Offensive Values'!$Q$6)/2,IF(G1="White Sox",('Offensive Values'!$P$7+'Offensive Values'!$Q$7)/2,IF(G1="Reds",('Offensive Values'!$P$8+'Offensive Values'!$Q$8)/2,IF(G1="Indians",('Offensive Values'!$P$9+'Offensive Values'!$Q$9)/2,IF(G1="Rockies",('Offensive Values'!$P$10+'Offensive Values'!$Q$10)/2,IF(G1="Tigers",('Offensive Values'!$P$11+'Offensive Values'!$Q$11)/2,IF(G1="Astros",('Offensive Values'!$P$12+'Offensive Values'!$Q$12)/2,IF(G1="Royals",('Offensive Values'!$P$13+'Offensive Values'!$Q$13)/2,IF(G1="Angels",('Offensive Values'!$P$14+'Offensive Values'!$Q$14)/2,IF(G1="Dodgers",('Offensive Values'!$P$15+'Offensive Values'!$Q$15)/2,IF(G1="Marlins",('Offensive Values'!$P$16+'Offensive Values'!$Q$16)/2,IF(G1="Brewers",('Offensive Values'!$P$17+'Offensive Values'!$Q$17)/2,IF(G1="Twins",('Offensive Values'!$P$18+'Offensive Values'!$Q$18)/2,IF(G1="Mets",('Offensive Values'!$P$19+'Offensive Values'!$Q$19)/2,IF(G1="Yankees",('Offensive Values'!$P$20+'Offensive Values'!$Q$20)/2,IF(G1="Athletics",('Offensive Values'!$P$21+'Offensive Values'!$Q$21)/2,IF(G1="Phillies",('Offensive Values'!$P$22+'Offensive Values'!$Q$22)/2,IF(G1="Pirates",('Offensive Values'!$P$23+'Offensive Values'!$Q$23)/2,IF(G1="Padres",('Offensive Values'!$P$24+'Offensive Values'!$Q$24)/2,IF(G1="Giants",('Offensive Values'!$P$25+'Offensive Values'!$Q$25)/2,IF(G1="Mariners",('Offensive Values'!$P$26+'Offensive Values'!$Q$26)/2,IF(G1="Cardinals",('Offensive Values'!$P$27+'Offensive Values'!$Q$27)/2,IF(G1="Rays",('Offensive Values'!$P$28+'Offensive Values'!$Q$28)/2,IF(G1="Rangers",('Offensive Values'!$P$29+'Offensive Values'!$Q$29)/2,IF(G1="Blue Jays",('Offensive Values'!$P$30+'Offensive Values'!$Q$30)/2,IF(G1="Nationals",('Offensive Values'!$P$31+'Offensive Values'!$Q$31)/2)))))))))))))))))))))))))))))) -> 1.0139246 | H2: 9 | I2: =IF(I1="Diamondbacks",('Offensive Values'!$P$2+'Offensive Values'!$Q$2)/2,IF(I1="Braves",('Offensive Values'!$P$3+'Offensive Values'!$Q$3)/2,IF(I1="Orioles",('Offensive Values'!$P$4+'Offensive Values'!$Q$4)/2,IF(I1="Red Sox",('Offensive Values'!$P$5+'Offensive Values'!$Q$5)/2,IF(I1="Cubs",('Offensive Values'!$P$6+'Offensive Values'!$Q$6)/2,IF(I1="White Sox",('Offensive Values'!$P$7+'Offensive Values'!$Q$7)/2,IF(I1="Reds",('Offensive Values'!$P$8+'Offensive Values'!$Q$8)/2,IF(I1="Indians",('Offensive Values'!$P$9+'Offensive Values'!$Q$9)/2,IF(I1="Rockies",('Offensive Values'!$P$10+'Offensive Values'!$Q$10)/2,IF(I1="Tigers",('Offensive Values'!$P$11+'Offensive Values'!$Q$11)/2,IF(I1="Astros",('Offensive Values'!$P$12+'Offensive Values'!$Q$12)/2,IF(I1="Royals",('Offensive Values'!$P$13+'Offensive Values'!$Q$13)/2,IF(I1="Angels",('Offensive Values'!$P$14+'Offensive Values'!$Q$14)/2,IF(I1="Dodgers",('Offensive Values'!$P$15+'Offensive Values'!$Q$15)/2,IF(I1="Marlins",('Offensive Values'!$P$16+'Offensive Values'!$Q$16)/2,IF(I1="Brewers",('Offensive Values'!$P$17+'Offensive Values'!$Q$17)/2,IF(I1="Twins",('Offensive Values'!$P$18+'Offensive Values'!$Q$18)/2,IF(I1="Mets",('Offensive Values'!$P$19+'Offensive Values'!$Q$19)/2,IF(I1="Yankees",('Offensive Values'!$P$20+'Offensive Values'!$Q$20)/2,IF(I1="Athletics",('Offensive Values'!$P$21+'Offensive Values'!$Q$21)/2,IF(I1="Phillies",('Offensive Values'!$P$22+'Offensive Values'!$Q$22)/2,IF(I1="Pirates",('Offensive Values'!$P$23+'Offensive Values'!$Q$23)/2,IF(I1="Padres",('Offensive Values'!$P$24+'Offensive Values'!$Q$24)/2,IF(I1="Giants",('Offensive Values'!$P$25+'Offensive Values'!$Q$25)/2,IF(I1="Mariners",('Offensive Values'!$P$26+'Offensive Values'!$Q$26)/2,IF(I1="Cardinals",('Offensive Values'!$P$27+'Offensive Values'!$Q$27)/2,IF(I1="Rays",('Offensive Values'!$P$28+'Offensive Values'!$Q$28)/2,IF(I1="Rangers",('Offensive Values'!$P$29+'Offensive Values'!$Q$29)/2,IF(I1="Blue Jays",('Offensive Values'!$P$30+'Offensive Values'!$Q$30)/2,IF(I1="Nationals",('Offensive Values'!$P$31+'Offensive Values'!$Q$31)/2)))))))))))))))))))))))))))))) -> 1.0157195 | J2: Offensive Value | K2: =IF(K1="Diamondbacks",('Offensive Values'!$P$2+'Offensive Values'!$Q$2)/2,IF(K1="Braves",('Offensive Values'!$P$3+'Offensive Values'!$Q$3)/2,IF(K1="Orioles",('Offensive Values'!$P$4+'Offensive Values'!$Q$4)/2,IF(K1="Red Sox",('Offensive Values'!$P$5+'Offensive Values'!$Q$5)/2,IF(K1="Cubs",('Offensive Values'!$P$6+'Offensive Values'!$Q$6)/2,IF(K1="White Sox",('Offensive Values'!$P$7+'Offensive Values'!$Q$7)/2,IF(K1="Reds",('Offensive Values'!$P$8+'Offensive Values'!$Q$8)/2,IF(K1="Indians",('Offensive Values'!$P$9+'Offensive Values'!$Q$9)/2,IF(K1="Rockies",('Offensive Values'!$P$10+'Offensive Values'!$Q$10)/2,IF(K1="Tigers",('Offensive Values'!$P$11+'Offensive Values'!$Q$11)/2,IF(K1="Astros",('Offensive Values'!$P$12+'Offensive Values'!$Q$12)/2,IF(K1="Royals",('Offensive Values'!$P$13+'Offensive Values'!$Q$13)/2,IF(K1="Angels",('Offensive Values'!$P$14+'Offensive Values'!$Q$14)/2,IF(K1="Dodgers",('Offensive Values'!$P$15+'Offensive Values'!$Q$15)/2,IF(K1="Marlins",('Offensive Values'!$P$16+'Offensive Values'!$Q$16)/2,IF(K1="Brewers",('Offensive Values'!$P$17+'Offensive Values'!$Q$17)/2,IF(K1="Twins",('Offensive Values'!$P$18+'Offensive Values'!$Q$18)/2,IF(K1="Mets",('Offensive Values'!$P$19+'Offensive Values'!$Q$19)/2,IF(K1="Yankees",('Offensive Values'!$P$20+'Offensive Values'!$Q$20)/2,IF(K1="Athletics",('Offensive Values'!$P$21+'Offensive Values'!$Q$21)/2,IF(K1="Phillies",('Offensive Values'!$P$22+'Offensive Values'!$Q$22)/2,IF(K1="Pirates",('Offensive Values'!$P$23+'Offensive Values'!$Q$23)/2,IF(K1="Padres",('Offensive Values'!$P$24+'Offensive Values'!$Q$24)/2,IF(K1="Giants",('Offensive Values'!$P$25+'Offensive Values'!$Q$25)/2,IF(K1="Mariners",('Offensive Values'!$P$26+'Offensive Values'!$Q$26)/2,IF(K1="Cardinals",('Offensive Values'!$P$27+'Offensive Values'!$Q$27)/2,IF(K1="Rays",('Offensive Values'!$P$28+'Offensive Values'!$Q$28)/2,IF(K1="Rangers",('Offensive Values'!$P$29+'Offensive Values'!$Q$29)/2,IF(K1="Blue Jays",('Offensive Values'!$P$30+'Offensive Values'!$Q$30)/2,IF(K1="Nationals",('Offensive Values'!$P$31+'Offensive Values'!$Q$31)/2)))))))))))))))))))))))))))))) -> 0.9794418 | L2: 7 | O2: Red Sox +10 | P2: 105 | Q2: =(0.51*1.05)-(0.49*1) -> 0.0455
A3: =AVERAGE('Starting Pitchers'!B31:E31)*(6/9) -> 2.1416667 | B3: Starting Pitcher | C3: =AVERAGE('Starting Pitchers'!B112:E112)*(6/9) -> 3.4883333 | D3: Exponent | E3: =AVERAGE(4.01,3.32,2.33,3.56)*(6/9) -> 2.2033333 | F3: Starting Pitcher | G3: =AVERAGE(3.5)*(6/9) -> 2.3333333 | H3: Exponent | I3: =AVERAGE('Starting Pitchers'!B106:E106)*(6/9) -> 1.8816667 | J3: Starting Pitcher | K3: =AVERAGE('Starting Pitchers'!B154:E154)*(6/9) -> 1.7233333 | L3: Exponent | M3: League ERA | O3: Marlins +82 | P3: -110 | Q3: =(0.6*0.909)-(0.4*1) -> 0.1454
A4: =IF(A1="Diamondbacks", AVERAGE('Bullpen Values'!$K$5:$N$5)*(3/9), IF(A1="Braves",AVERAGE('Bullpen Values'!$K$6:$N$6)*(3/9),IF(A1="Orioles",AVERAGE('Bullpen Values'!$K$7:$N$7)*(3/9),IF(A1="Red Sox",AVERAGE('Bullpen Values'!$K$8:$N$8)*(3/9),IF(A1="Cubs",AVERAGE('Bullpen Values'!$K$9:$N$9)*(3/9),IF(A1="White Sox",AVERAGE('Bullpen Values'!$K$10:$N$10)*(3/9),IF(A1="Reds",AVERAGE('Bullpen Values'!$K$11:$N$11)*(3/9),IF(A1="Indians",AVERAGE('Bullpen Values'!$K$12:$N$12)*(3/9),IF(A1="Rockies",AVERAGE('Bullpen Values'!$K$13:$N$13)*(3/9),IF(A1="Tigers",AVERAGE('Bullpen Values'!$K$14:$N$14)*(3/9),IF(A1="Astros",AVERAGE('Bullpen Values'!$K$15:$N$15)*(3/9),IF(A1="Royals",AVERAGE('Bullpen Values'!$K$16:$N$16)*(3/9),IF(A1="Angels",AVERAGE('Bullpen Values'!$K$17:$N$17)*(3/9),IF(A1="Dodgers",AVERAGE('Bullpen Values'!$K$18:$N$18)*(3/9),IF(A1="Marlins",AVERAGE('Bullpen Values'!$K$19:$N$19)*(3/9),IF(A1="Brewers",AVERAGE('Bullpen Values'!$K$20:$N$20)*(3/9),IF(A1="Twins",AVERAGE('Bullpen Values'!$K$21:$N$21)*(3/9),IF(A1="Mets",AVERAGE('Bullpen Values'!$K$22:$N$22)*(3/9),IF(A1="Yankees",AVERAGE('Bullpen Values'!$K$23:$N$23)*(3/9),IF(A1="Athletics",AVERAGE('Bullpen Values'!$K$24:$N$24)*(3/9),IF(A1="Phillies",AVERAGE('Bullpen Values'!$K$25:$N$25)*(3/9),IF(A1="Pirates",AVERAGE('Bullpen Values'!$K$26:$N$26)*(3/9),IF(A1="Padres",AVERAGE('Bullpen Values'!$K$27:$N$27)*(3/9),IF(A1="Giants",AVERAGE('Bullpen Values'!$K$28:$N$28)*(3/9),IF(A1="Mariners",AVERAGE('Bullpen Values'!$K$29:$N$29)*(3/9),IF(A1="Cardinals",AVERAGE('Bullpen Values'!$K$30:$N$30)*(3/9),IF(A1="Rays",AVERAGE('Bullpen Values'!$K$31:$N$31)*(3/9),IF(A1="Rangers",AVERAGE('Bullpen Values'!$K$32:$N$32)*(3/9),IF(A1="Blue Jays",AVERAGE('Bullpen Values'!$K$33:$N$33)*(3/9),IF(A1="Nationals",AVERAGE('Bullpen Values'!$K$34:$N$34)*(3/9))))))))))))))))))))))))))))))) -> 1.2244444 | B4: Bullpen Value | C4: =IF(C1="Diamondbacks", AVERAGE('Bullpen Values'!$K$5:$N$5)*(3/9), IF(C1="Braves",AVERAGE('Bullpen Values'!$K$6:$N$6)*(3/9),IF(C1="Orioles",AVERAGE('Bullpen Values'!$K$7:$N$7)*(3/9),IF(C1="Red Sox",AVERAGE('Bullpen Values'!$K$8:$N$8)*(3/9),IF(C1="Cubs",AVERAGE('Bullpen Values'!$K$9:$N$9)*(3/9),IF(C1="White Sox",AVERAGE('Bullpen Values'!$K$10:$N$10)*(3/9),IF(C1="Reds",AVERAGE('Bullpen Values'!$K$11:$N$11)*(3/9),IF(C1="Indians",AVERAGE('Bullpen Values'!$K$12:$N$12)*(3/9),IF(C1="Rockies",AVERAGE('Bullpen Values'!$K$13:$N$13)*(3/9),IF(C1="Tigers",AVERAGE('Bullpen Values'!$K$14:$N$14)*(3/9),IF(C1="Astros",AVERAGE('Bullpen Values'!$K$15:$N$15)*(3/9),IF(C1="Royals",AVERAGE('Bullpen Values'!$K$16:$N$16)*(3/9),IF(C1="Angels",AVERAGE('Bullpen Values'!$K$17:$N$17)*(3/9),IF(C1="Dodgers",AVERAGE('Bullpen Values'!$K$18:$N$18)*(3/9),IF(C1="Marlins",AVERAGE('Bullpen Values'!$K$19:$N$19)*(3/9),IF(C1="Brewers",AVERAGE('Bullpen Values'!$K$20:$N$20)*(3/9),IF(C1="Twins",AVERAGE('Bullpen Values'!$K$21:$N$21)*(3/9),IF(C1="Mets",AVERAGE('Bullpen Values'!$K$22:$N$22)*(3/9),IF(C1="Yankees",AVERAGE('Bullpen Values'!$K$23:$N$23)*(3/9),IF(C1="Athletics",AVERAGE('Bullpen Values'!$K$24:$N$24)*(3/9),IF(C1="Phillies",AVERAGE('Bullpen Values'!$K$25:$N$25)*(3/9),IF(C1="Pirates",AVERAGE('Bullpen Values'!$K$26:$N$26)*(3/9),IF(C1="Padres",AVERAGE('Bullpen Values'!$K$27:$N$27)*(3/9),IF(C1="Giants",AVERAGE('Bullpen Values'!$K$28:$N$28)*(3/9),IF(C1="Mariners",AVERAGE('Bullpen Values'!$K$29:$N$29)*(3/9),IF(C1="Cardinals",AVERAGE('Bullpen Values'!$K$30:$N$30)*(3/9),IF(C1="Rays",AVERAGE('Bullpen Values'!$K$31:$N$31)*(3/9),IF(C1="Rangers",AVERAGE('Bullpen Values'!$K$32:$N$32)*(3/9),IF(C1="Blue Jays",AVERAGE('Bullpen Values'!$K$33:$N$33)*(3/9),IF(C1="Nationals",AVERAGE('Bullpen Values'!$K$34:$N$34)*(3/9))))))))))))))))))))))))))))))) -> 1.35 | D4: =IF(D2=6.5,1.67,IF(D2=7,1.72,IF(D2=7.5,1.76,IF(D2=8,1.8,IF(D2=8.5,1.84,IF(D2=9,1.88,IF(D2=9.5,1.92,IF(D2=10,1.95,IF(D2=10.5,1.98,IF(D2=11,2.01,IF(D2=11.5,2.04,IF(D2=12,2.07,IF(D2=12.5,2.1,IF(D2=13,2.12)))))))))))))) -> 1.8 | E4: =IF(E1="Diamondbacks", AVERAGE('Bullpen Values'!$K$5:$N$5)*(3/9), IF(E1="Braves",AVERAGE('Bullpen Values'!$K$6:$N$6)*(3/9),IF(E1="Orioles",AVERAGE('Bullpen Values'!$K$7:$N$7)*(3/9),IF(E1="Red Sox",AVERAGE('Bullpen Values'!$K$8:$N$8)*(3/9),IF(E1="Cubs",AVERAGE('Bullpen Values'!$K$9:$N$9)*(3/9),IF(E1="White Sox",AVERAGE('Bullpen Values'!$K$10:$N$10)*(3/9),IF(E1="Reds",AVERAGE('Bullpen Values'!$K$11:$N$11)*(3/9),IF(E1="Indians",AVERAGE('Bullpen Values'!$K$12:$N$12)*(3/9),IF(E1="Rockies",AVERAGE('Bullpen Values'!$K$13:$N$13)*(3/9),IF(E1="Tigers",AVERAGE('Bullpen Values'!$K$14:$N$14)*(3/9),IF(E1="Astros",AVERAGE('Bullpen Values'!$K$15:$N$15)*(3/9),IF(E1="Royals",AVERAGE('Bullpen Values'!$K$16:$N$16)*(3/9),IF(E1="Angels",AVERAGE('Bullpen Values'!$K$17:$N$17)*(3/9),IF(E1="Dodgers",AVERAGE('Bullpen Values'!$K$18:$N$18)*(3/9),IF(E1="Marlins",AVERAGE('Bullpen Values'!$K$19:$N$19)*(3/9),IF(E1="Brewers",AVERAGE('Bullpen Values'!$K$20:$N$20)*(3/9),IF(E1="Twins",AVERAGE('Bullpen Values'!$K$21:$N$21)*(3/9),IF(E1="Mets",AVERAGE('Bullpen Values'!$K$22:$N$22)*(3/9),IF(E1="Yankees",AVERAGE('Bullpen Values'!$K$23:$N$23)*(3/9),IF(E1="Athletics",AVERAGE('Bullpen Values'!$K$24:$N$24)*(3/9),IF(E1="Phillies",AVERAGE('Bullpen Values'!$K$25:$N$25)*(3/9),IF(E1="Pirates",AVERAGE('Bullpen Values'!$K$26:$N$26)*(3/9),IF(E1="Padres",AVERAGE('Bullpen Values'!$K$27:$N$27)*(3/9),IF(E1="Giants",AVERAGE('Bullpen Values'!$K$28:$N$28)*(3/9),IF(E1="Mariners",AVERAGE('Bullpen Values'!$K$29:$N$29)*(3/9),IF(E1="Cardinals",AVERAGE('Bullpen Values'!$K$30:$N$30)*(3/9),IF(E1="Rays",AVERAGE('Bullpen Values'!$K$31:$N$31)*(3/9),IF(E1="Rangers",AVERAGE('Bullpen Values'!$K$32:$N$32)*(3/9),IF(E1="Blue Jays",AVERAGE('Bullpen Values'!$K$33:$N$33)*(3/9),IF(E1="Nationals",AVERAGE('Bullpen Values'!$K$34:$N$34)*(3/9))))))))))))))))))))))))))))))) -> 1.2366667 | F4: Bullpen Value | G4: =IF(G1="Diamondbacks", AVERAGE('Bullpen Values'!$K$5:$N$5)*(3/9), IF(G1="Braves",AVERAGE('Bullpen Values'!$K$6:$N$6)*(3/9),IF(G1="Orioles",AVERAGE('Bullpen Values'!$K$7:$N$7)*(3/9),IF(G1="Red Sox",AVERAGE('Bullpen Values'!$K$8:$N$8)*(3/9),IF(G1="Cubs",AVERAGE('Bullpen Values'!$K$9:$N$9)*(3/9),IF(G1="White Sox",AVERAGE('Bullpen Values'!$K$10:$N$10)*(3/9),IF(G1="Reds",AVERAGE('Bullpen Values'!$K$11:$N$11)*(3/9),IF(G1="Indians",AVERAGE('Bullpen Values'!$K$12:$N$12)*(3/9),IF(G1="Rockies",AVERAGE('Bullpen Values'!$K$13:$N$13)*(3/9),IF(G1="Tigers",AVERAGE('Bullpen Values'!$K$14:$N$14)*(3/9),IF(G1="Astros",AVERAGE('Bullpen Values'!$K$15:$N$15)*(3/9),IF(G1="Royals",AVERAGE('Bullpen Values'!$K$16:$N$16)*(3/9),IF(G1="Angels",AVERAGE('Bullpen Values'!$K$17:$N$17)*(3/9),IF(G1="Dodgers",AVERAGE('Bullpen Values'!$K$18:$N$18)*(3/9),IF(G1="Marlins",AVERAGE('Bullpen Values'!$K$19:$N$19)*(3/9),IF(G1="Brewers",AVERAGE('Bullpen Values'!$K$20:$N$20)*(3/9),IF(G1="Twins",AVERAGE('Bullpen Values'!$K$21:$N$21)*(3/9),IF(G1="Mets",AVERAGE('Bullpen Values'!$K$22:$N$22)*(3/9),IF(G1="Yankees",AVERAGE('Bullpen Values'!$K$23:$N$23)*(3/9),IF(G1="Athletics",AVERAGE('Bullpen Values'!$K$24:$N$24)*(3/9),IF(G1="Phillies",AVERAGE('Bullpen Values'!$K$25:$N$25)*(3/9),IF(G1="Pirates",AVERAGE('Bullpen Values'!$K$26:$N$26)*(3/9),IF(G1="Padres",AVERAGE('Bullpen Values'!$K$27:$N$27)*(3/9),IF(G1="Giants",AVERAGE('Bullpen Values'!$K$28:$N$28)*(3/9),IF(G1="Mariners",AVERAGE('Bullpen Values'!$K$29:$N$29)*(3/9),IF(G1="Cardinals",AVERAGE('Bullpen Values'!$K$30:$N$30)*(3/9),IF(G1="Rays",AVERAGE('Bullpen Values'!$K$31:$N$31)*(3/9),IF(G1="Rangers",AVERAGE('Bullpen Values'!$K$32:$N$32)*(3/9),IF(G1="Blue Jays",AVERAGE('Bullpen Values'!$K$33:$N$33)*(3/9),IF(G1="Nationals",AVERAGE('Bullpen Values'!$K$34:$N$34)*(3/9))))))))))))))))))))))))))))))) -> 1.1111111 | H4: =IF(H2=6.5,1.67,IF(H2=7,1.72,IF(H2=7.5,1.76,IF(H2=8,1.8,IF(H2=8.5,1.84,IF(H2=9,1.88,IF(H2=9.5,1.92,IF(H2=10,1.95,IF(H2=10.5,1.98,IF(H2=11,2.01,IF(H2=11.5,2.04,IF(H2=12,2.07,IF(H2=12.5,2.1,IF(H2=13,2.12)))))))))))))) -> 1.88 | I4: =IF(I1="Diamondbacks", AVERAGE('Bullpen Values'!$K$5:$N$5)*(3/9), IF(I1="Braves",AVERAGE('Bullpen Values'!$K$6:$N$6)*(3/9),IF(I1="Orioles",AVERAGE('Bullpen Values'!$K$7:$N$7)*(3/9),IF(I1="Red Sox",AVERAGE('Bullpen Values'!$K$8:$N$8)*(3/9),IF(I1="Cubs",AVERAGE('Bullpen Values'!$K$9:$N$9)*(3/9),IF(I1="White Sox",AVERAGE('Bullpen Values'!$K$10:$N$10)*(3/9),IF(I1="Reds",AVERAGE('Bullpen Values'!$K$11:$N$11)*(3/9),IF(I1="Indians",AVERAGE('Bullpen Values'!$K$12:$N$12)*(3/9),IF(I1="Rockies",AVERAGE('Bullpen Values'!$K$13:$N$13)*(3/9),IF(I1="Tigers",AVERAGE('Bullpen Values'!$K$14:$N$14)*(3/9),IF(I1="Astros",AVERAGE('Bullpen Values'!$K$15:$N$15)*(3/9),IF(I1="Royals",AVERAGE('Bullpen Values'!$K$16:$N$16)*(3/9),IF(I1="Angels",AVERAGE('Bullpen Values'!$K$17:$N$17)*(3/9),IF(I1="Dodgers",AVERAGE('Bullpen Values'!$K$18:$N$18)*(3/9),IF(I1="Marlins",AVERAGE('Bullpen Values'!$K$19:$N$19)*(3/9),IF(I1="Brewers",AVERAGE('Bullpen Values'!$K$20:$N$20)*(3/9),IF(I1="Twins",AVERAGE('Bullpen Values'!$K$21:$N$21)*(3/9),IF(I1="Mets",AVERAGE('Bullpen Values'!$K$22:$N$22)*(3/9),IF(I1="Yankees",AVERAGE('Bullpen Values'!$K$23:$N$23)*(3/9),IF(I1="Athletics",AVERAGE('Bullpen Values'!$K$24:$N$24)*(3/9),IF(I1="Phillies",AVERAGE('Bullpen Values'!$K$25:$N$25)*(3/9),IF(I1="Pirates",AVERAGE('Bullpen Values'!$K$26:$N$26)*(3/9),IF(I1="Padres",AVERAGE('Bullpen Values'!$K$27:$N$27)*(3/9),IF(I1="Giants",AVERAGE('Bullpen Values'!$K$28:$N$28)*(3/9),IF(I1="Mariners",AVERAGE('Bullpen Values'!$K$29:$N$29)*(3/9),IF(I1="Cardinals",AVERAGE('Bullpen Values'!$K$30:$N$30)*(3/9),IF(I1="Rays",AVERAGE('Bullpen Values'!$K$31:$N$31)*(3/9),IF(I1="Rangers",AVERAGE('Bullpen Values'!$K$32:$N$32)*(3/9),IF(I1="Blue Jays",AVERAGE('Bullpen Values'!$K$33:$N$33)*(3/9),IF(I1="Nationals",AVERAGE('Bullpen Values'!$K$34:$N$34)*(3/9))))))))))))))))))))))))))))))) -> 1.3722222 | J4: Bullpen Value | K4: =IF(K1="Diamondbacks", AVERAGE('Bullpen Values'!$K$5:$N$5)*(3/9), IF(K1="Braves",AVERAGE('Bullpen Values'!$K$6:$N$6)*(3/9),IF(K1="Orioles",AVERAGE('Bullpen Values'!$K$7:$N$7)*(3/9),IF(K1="Red Sox",AVERAGE('Bullpen Values'!$K$8:$N$8)*(3/9),IF(K1="Cubs",AVERAGE('Bullpen Values'!$K$9:$N$9)*(3/9),IF(K1="White Sox",AVERAGE('Bullpen Values'!$K$10:$N$10)*(3/9),IF(K1="Reds",AVERAGE('Bullpen Values'!$K$11:$N$11)*(3/9),IF(K1="Indians",AVERAGE('Bullpen Values'!$K$12:$N$12)*(3/9),IF(K1="Rockies",AVERAGE('Bullpen Values'!$K$13:$N$13)*(3/9),IF(K1="Tigers",AVERAGE('Bullpen Values'!$K$14:$N$14)*(3/9),IF(K1="Astros",AVERAGE('Bullpen Values'!$K$15:$N$15)*(3/9),IF(K1="Royals",AVERAGE('Bullpen Values'!$K$16:$N$16)*(3/9),IF(K1="Angels",AVERAGE('Bullpen Values'!$K$17:$N$17)*(3/9),IF(K1="Dodgers",AVERAGE('Bullpen Values'!$K$18:$N$18)*(3/9),IF(K1="Marlins",AVERAGE('Bullpen Values'!$K$19:$N$19)*(3/9),IF(K1="Brewers",AVERAGE('Bullpen Values'!$K$20:$N$20)*(3/9),IF(K1="Twins",AVERAGE('Bullpen Values'!$K$21:$N$21)*(3/9),IF(K1="Mets",AVERAGE('Bullpen Values'!$K$22:$N$22)*(3/9),IF(K1="Yankees",AVERAGE('Bullpen Values'!$K$23:$N$23)*(3/9),IF(K1="Athletics",AVERAGE('Bullpen Values'!$K$24:$N$24)*(3/9),IF(K1="Phillies",AVERAGE('Bullpen Values'!$K$25:$N$25)*(3/9),IF(K1="Pirates",AVERAGE('Bullpen Values'!$K$26:$N$26)*(3/9),IF(K1="Padres",AVERAGE('Bullpen Values'!$K$27:$N$27)*(3/9),IF(K1="Giants",AVERAGE('Bullpen Values'!$K$28:$N$28)*(3/9),IF(K1="Mariners",AVERAGE('Bullpen Values'!$K$29:$N$29)*(3/9),IF(K1="Cardinals",AVERAGE('Bullpen Values'!$K$30:$N$30)*(3/9),IF(K1="Rays",AVERAGE('Bullpen Values'!$K$31:$N$31)*(3/9),IF(K1="Rangers",AVERAGE('Bullpen Values'!$K$32:$N$32)*(3/9),IF(K1="Blue Jays",AVERAGE('Bullpen Values'!$K$33:$N$33)*(3/9),IF(K1="Nationals",AVERAGE('Bullpen Values'!$K$34:$N$34)*(3/9))))))))))))))))))))))))))))))) -> 1.4811111 | L4: =IF(L2=6.5,1.67,IF(L2=7,1.72,IF(L2=7.5,1.76,IF(L2=8,1.8,IF(L2=8.5,1.84,IF(L2=9,1.88,IF(L2=9.5,1.92,IF(L2=10,1.95,IF(L2=10.5,1.98,IF(L2=11,2.01,IF(L2=11.5,2.04,IF(L2=12,2.07,IF(L2=12.5,2.1,IF(L2=13,2.12)))))))))))))) -> 1.72 | M4: 4.05 | O4: Blue Jays +10 | P4: -132 | Q4: =(0.58*0.7)-(0.42*1) -> -0.014
A5: =(A3+A4)/$M$4 -> 0.83113855 | B5: Pitching Value | C5: =(C3+C4)/$M$4 -> 1.1946502 | E5: =(E3+E4)/$M$4 -> 0.84938272 | F5: Pitching Value | G5: =(G3+G4)/$M$4 -> 0.85048011 | I5: =(I3+I4)/$M$4 -> 0.80342936 | J5: Pitching Value | K5: =(K3+K4)/$M$4 -> 0.79122085 | M5: League xR | O5: Tigers +40 | P5: 133 | Q5: =(0.52*1.33)-(0.48*1) -> 0.2116
A6: =A2*C5*M6 -> 4.8533536 | B6: xRuns | C6: =C2*A5*M6 -> 3.3759014 | E6: =E2*G5*M6 -> 3.8735307 | F6: xRuns | G6: =G2*E5*M6 -> 3.7548756 | I6: =I2*K5*M6 -> 3.5039508 | J6: xRuns | K6: =K2*I5*M6 -> 3.4309376 | M6: 4.36 | O6: Diamondbacks +30 | P6: 170 | Q6: =(0.42*1.7)-(0.58*1) -> 0.134
A7: =POWER(A6,D4)/(POWER(A6,D4)+(POWER(C6,D4))) -> 0.6577793 | B7: Win % | C7: =POWER(C6,D4)/(POWER(C6,D4)+(POWER(A6,D4))) -> 0.3422207 | E7: =POWER(E6,H4)/(POWER(E6,H4)+(POWER(G6,H4))) -> 0.51461813 | F7: Win % | G7: =POWER(G6,H4)/(POWER(G6,H4)+(POWER(E6,H4))) -> 0.48538187 | I7: =POWER(I6,L4)/(POWER(I6,L4)+(POWER(K6,L4))) -> 0.50905375 | J7: Win % | K7: =POWER(K6,L4)/(POWER(K6,L4)+(POWER(I6,L4))) -> 0.49094625 | O7: Rockies +10 | P7: 115 | Q7: =(0.49*1.15)-(0.51*1) -> 0.0535
A8: =IF(A7<0.5,100/(A7/1)-100,((A7*100)/(1-(A7/1)))*-1) -> -192.20909 | B8: "True" Odds | C8: =IF(C7<0.5,100/(C7/1)-100,((C7*100)/(1-(C7/1)))*-1) -> 192.20909 | E8: =IF(E7<0.5,100/(E7/1)-100,((E7*100)/(1-(E7/1)))*-1) -> -106.02335 | F8: "True" Odds | G8: =IF(G7<0.5,100/(G7/1)-100,((G7*100)/(1-(G7/1)))*-1) -> 106.02335 | I8: =IF(I7<0.5,100/(I7/1)-100,((I7*100)/(1-(I7/1)))*-1) -> -103.68829 | J8: "True" Odds | K8: =IF(K7<0.5,100/(K7/1)-100,((K7*100)/(1-(K7/1)))*-1) -> 103.68829 | O8: Mariners +15 | P8: 150 | Q8: =(0.41*1.5)-(0.59*1) -> 0.025
A9: Dodgers | B9: Teams | C9: Braves | D9: Game Total | E9: Rays | F9: Teams | G9: Rangers | H9: Game Total | I9: Astros | J9: Teams | K9: Blue Jays | L9: Game Total | O9: Mets +60 | P9: 162 | Q9: =(0.48*1.62)-(0.52*1) -> 0.2576
A10: =IF(A9="Diamondbacks",('Offensive Values'!$P$2+'Offensive Values'!$Q$2)/2,IF(A9="Braves",('Offensive Values'!$P$3+'Offensive Values'!$Q$3)/2,IF(A9="Orioles",('Offensive Values'!$P$4+'Offensive Values'!$Q$4)/2,IF(A9="Red Sox",('Offensive Values'!$P$5+'Offensive Values'!$Q$5)/2,IF(A9="Cubs",('Offensive Values'!$P$6+'Offensive Values'!$Q$6)/2,IF(A9="White Sox",('Offensive Values'!$P$7+'Offensive Values'!$Q$7)/2,IF(A9="Reds",('Offensive Values'!$P$8+'Offensive Values'!$Q$8)/2,IF(A9="Indians",('Offensive Values'!$P$9+'Offensive Values'!$Q$9)/2,IF(A9="Rockies",('Offensive Values'!$P$10+'Offensive Values'!$Q$10)/2,IF(A9="Tigers",('Offensive Values'!$P$11+'Offensive Values'!$Q$11)/2,IF(A9="Astros",('Offensive Values'!$P$12+'Offensive Values'!$Q$12)/2,IF(A9="Royals",('Offensive Values'!$P$13+'Offensive Values'!$Q$13)/2,IF(A9="Angels",('Offensive Values'!$P$14+'Offensive Values'!$Q$14)/2,IF(A9="Dodgers",('Offensive Values'!$P$15+'Offensive Values'!$Q$15)/2,IF(A9="Marlins",('Offensive Values'!$P$16+'Offensive Values'!$Q$16)/2,IF(A9="Brewers",('Offensive Values'!$P$17+'Offensive Values'!$Q$17)/2,IF(A9="Twins",('Offensive Values'!$P$18+'Offensive Values'!$Q$18)/2,IF(A9="Mets",('Offensive Values'!$P$19+'Offensive Values'!$Q$19)/2,IF(A9="Yankees",('Offensive Values'!$P$20+'Offensive Values'!$Q$20)/2,IF(A9="Athletics",('Offensive Values'!$P$21+'Offensive Values'!$Q$21)/2,IF(A9="Phillies",('Offensive Values'!$P$22+'Offensive Values'!$Q$22)/2,IF(A9="Pirates",('Offensive Values'!$P$23+'Offensive Values'!$Q$23)/2,IF(A9="Padres",('Offensive Values'!$P$24+'Offensive Values'!$Q$24)/2,IF(A9="Giants",('Offensive Values'!$P$25+'Offensive Values'!$Q$25)/2,IF(A9="Mariners",('Offensive Values'!$P$26+'Offensive Values'!$Q$26)/2,IF(A9="Cardinals",('Offensive Values'!$P$27+'Offensive Values'!$Q$27)/2,IF(A9="Rays",('Offensive Values'!$P$28+'Offensive Values'!$Q$28)/2,IF(A9="Rangers",('Offensive Values'!$P$29+'Offensive Values'!$Q$29)/2,IF(A9="Blue Jays",('Offensive Values'!$P$30+'Offensive Values'!$Q$30)/2,IF(A9="Nationals",('Offensive Values'!$P$31+'Offensive Values'!$Q$31)/2)))))))))))))))))))))))))))))) -> 1.0573364 | B10: Offensive Value | C10: =IF(C9="Diamondbacks",('Offensive Values'!$P$2+'Offensive Values'!$Q$2)/2,IF(C9="Braves",('Offensive Values'!$P$3+'Offensive Values'!$Q$3)/2,IF(C9="Orioles",('Offensive Values'!$P$4+'Offensive Values'!$Q$4)/2,IF(C9="Red Sox",('Offensive Values'!$P$5+'Offensive Values'!$Q$5)/2,IF(C9="Cubs",('Offensive Values'!$P$6+'Offensive Values'!$Q$6)/2,IF(C9="White Sox",('Offensive Values'!$P$7+'Offensive Values'!$Q$7)/2,IF(C9="Reds",('Offensive Values'!$P$8+'Offensive Values'!$Q$8)/2,IF(C9="Indians",('Offensive Values'!$P$9+'Offensive Values'!$Q$9)/2,IF(C9="Rockies",('Offensive Values'!$P$10+'Offensive Values'!$Q$10)/2,IF(C9="Tigers",('Offensive Values'!$P$11+'Offensive Values'!$Q$11)/2,IF(C9="Astros",('Offensive Values'!$P$12+'Offensive Values'!$Q$12)/2,IF(C9="Royals",('Offensive Values'!$P$13+'Offensive Values'!$Q$13)/2,IF(C9="Angels",('Offensive Values'!$P$14+'Offensive Values'!$Q$14)/2,IF(C9="Dodgers",('Offensive Values'!$P$15+'Offensive Values'!$Q$15)/2,IF(C9="Marlins",('Offensive Values'!$P$16+'Offensive Values'!$Q$16)/2,IF(C9="Brewers",('Offensive Values'!$P$17+'Offensive Values'!$Q$17)/2,IF(C9="Twins",('Offensive Values'!$P$18+'Offensive Values'!$Q$18)/2,IF(C9="Mets",('Offensive Values'!$P$19+'Offensive Values'!$Q$19)/2,IF(C9="Yankees",('Offensive Values'!$P$20+'Offensive Values'!$Q$20)/2,IF(C9="Athletics",('Offensive Values'!$P$21+'Offensive Values'!$Q$21)/2,IF(C9="Phillies",('Offensive Values'!$P$22+'Offensive Values'!$Q$22)/2,IF(C9="Pirates",('Offensive Values'!$P$23+'Offensive Values'!$Q$23)/2,IF(C9="Padres",('Offensive Values'!$P$24+'Offensive Values'!$Q$24)/2,IF(C9="Giants",('Offensive Values'!$P$25+'Offensive Values'!$Q$25)/2,IF(C9="Mariners",('Offensive Values'!$P$26+'Offensive Values'!$Q$26)/2,IF(C9="Cardinals",('Offensive Values'!$P$27+'Offensive Values'!$Q$27)/2,IF(C9="Rays",('Offensive Values'!$P$28+'Offensive Values'!$Q$28)/2,IF(C9="Rangers",('Offensive Values'!$P$29+'Offensive Values'!$Q$29)/2,IF(C9="Blue Jays",('Offensive Values'!$P$30+'Offensive Values'!$Q$30)/2,IF(C9="Nationals",('Offensive Values'!$P$31+'Offensive Values'!$Q$31)/2)))))))))))))))))))))))))))))) -> 1.0554505 | D10: 8.5 | E10: =IF(E9="Diamondbacks",('Offensive Values'!$P$2+'Offensive Values'!$Q$2)/2,IF(E9="Braves",('Offensive Values'!$P$3+'Offensive Values'!$Q$3)/2,IF(E9="Orioles",('Offensive Values'!$P$4+'Offensive Values'!$Q$4)/2,IF(E9="Red Sox",('Offensive Values'!$P$5+'Offensive Values'!$Q$5)/2,IF(E9="Cubs",('Offensive Values'!$P$6+'Offensive Values'!$Q$6)/2,IF(E9="White Sox",('Offensive Values'!$P$7+'Offensive Values'!$Q$7)/2,IF(E9="Reds",('Offensive Values'!$P$8+'Offensive Values'!$Q$8)/2,IF(E9="Indians",('Offensive Values'!$P$9+'Offensive Values'!$Q$9)/2,IF(E9="Rockies",('Offensive Values'!$P$10+'Offensive Values'!$Q$10)/2,IF(E9="Tigers",('Offensive Values'!$P$11+'Offensive Values'!$Q$11)/2,IF(E9="Astros",('Offensive Values'!$P$12+'Offensive Values'!$Q$12)/2,IF(E9="Royals",('Offensive Values'!$P$13+'Offensive Values'!$Q$13)/2,IF(E9="Angels",('Offensive Values'!$P$14+'Offensive Values'!$Q$14)/2,IF(E9="Dodgers",('Offensive Values'!$P$15+'Offensive Values'!$Q$15)/2,IF(E9="Marlins",('Offensive Values'!$P$16+'Offensive Values'!$Q$16)/2,IF(E9="Brewers",('Offensive Values'!$P$17+'Offensive Values'!$Q$17)/2,IF(E9="Twins",('Offensive Values'!$P$18+'Offensive Values'!$Q$18)/2,IF(E9="Mets",('Offensive Values'!$P$19+'Offensive Values'!$Q$19)/2,IF(E9="Yankees",('Offensive Values'!$P$20+'Offensive Values'!$Q$20)/2,IF(E9="Athletics",('Offensive Values'!$P$21+'Offensive Values'!$Q$21)/2,IF(E9="Phillies",('Offensive Values'!$P$22+'Offensive Values'!$Q$22)/2,IF(E9="Pirates",('Offensive Values'!$P$23+'Offensive Values'!$Q$23)/2,IF(E9="Padres",('Offensive Values'!$P$24+'Offensive Values'!$Q$24)/2,IF(E9="Giants",('Offensive Values'!$P$25+'Offensive Values'!$Q$25)/2,IF(E9="Mariners",('Offensive Values'!$P$26+'Offensive Values'!$Q$26)/2,IF(E9="Cardinals",('Offensive Values'!$P$27+'Offensive Values'!$Q$27)/2,IF(E9="Rays",('Offensive Values'!$P$28+'Offensive Values'!$Q$28)/2,IF(E9="Rangers",('Offensive Values'!$P$29+'Offensive Values'!$Q$29)/2,IF(E9="Blue Jays",('Offensive Values'!$P$30+'Offensive Values'!$Q$30)/2,IF(E9="Nationals",('Offensive Values'!$P$31+'Offensive Values'!$Q$31)/2)))))))))))))))))))))))))))))) -> 0.98598443 | F10: Offensive Value | G10: =IF(G9="Diamondbacks",('Offensive Values'!$P$2+'Offensive Values'!$Q$2)/2,IF(G9="Braves",('Offensive Values'!$P$3+'Offensive Values'!$Q$3)/2,IF(G9="Orioles",('Offensive Values'!$P$4+'Offensive Values'!$Q$4)/2,IF(G9="Red Sox",('Offensive Values'!$P$5+'Offensive Values'!$Q$5)/2,IF(G9="Cubs",('Offensive Values'!$P$6+'Offensive Values'!$Q$6)/2,IF(G9="White Sox",('Offensive Values'!$P$7+'Offensive Values'!$Q$7)/2,IF(G9="Reds",('Offensive Values'!$P$8+'Offensive Values'!$Q$8)/2,IF(G9="Indians",('Offensive Values'!$P$9+'Offensive Values'!$Q$9)/2,IF(G9="Rockies",('Offensive Values'!$P$10+'Offensive Values'!$Q$10)/2,IF(G9="Tigers",('Offensive Values'!$P$11+'Offensive Values'!$Q$11)/2,IF(G9="Astros",('Offensive Values'!$P$12+'Offensive Values'!$Q$12)/2,IF(G9="Royals",('Offensive Values'!$P$13+'Offensive Values'!$Q$13)/2,IF(G9="Angels",('Offensive Values'!$P$14+'Offensive Values'!$Q$14)/2,IF(G9="Dodgers",('Offensive Values'!$P$15+'Offensive Values'!$Q$15)/2,IF(G9="Marlins",('Offensive Values'!$P$16+'Offensive Values'!$Q$16)/2,IF(G9="Brewers",('Offensive Values'!$P$17+'Offensive Values'!$Q$17)/2,IF(G9="Twins",('Offensive Values'!$P$18+'Offensive Values'!$Q$18)/2,IF(G9="Mets",('Offensive Values'!$P$19+'Offensive Values'!$Q$19)/2,IF(G9="Yankees",('Offensive Values'!$P$20+'Offensive Values'!$Q$20)/2,IF(G9="Athletics",('Offensive Values'!$P$21+'Offensive Values'!$Q$21)/2,IF(G9="Phillies",('Offensive Values'!$P$22+'Offensive Values'!$Q$22)/2,IF(G9="Pirates",('Offensive Values'!$P$23+'Offensive Values'!$Q$23)/2,IF(G9="Padres",('Offensive Values'!$P$24+'Offensive Values'!$Q$24)/2,IF(G9="Giants",('Offensive Values'!$P$25+'Offensive Values'!$Q$25)/2,IF(G9="Mariners",('Offensive Values'!$P$26+'Offensive Values'!$Q$26)/2,IF(G9="Cardinals",('Offensive Values'!$P$27+'Offensive Values'!$Q$27)/2,IF(G9="Rays",('Offensive Values'!$P$28+'Offensive Values'!$Q$28)/2,IF(G9="Rangers",('Offensive Values'!$P$29+'Offensive Values'!$Q$29)/2,IF(G9="Blue Jays",('Offensive Values'!$P$30+'Offensive Values'!$Q$30)/2,IF(G9="Nationals",('Offensive Values'!$P$31+'Offensive Values'!$Q$31)/2)))))))))))))))))))))))))))))) -> 0.96488017 | H10: 8 | I10: =IF(I9="Diamondbacks",('Offensive Values'!$P$2+'Offensive Values'!$Q$2)/2,IF(I9="Braves",('Offensive Values'!$P$3+'Offensive Values'!$Q$3)/2,IF(I9="Orioles",('Offensive Values'!$P$4+'Offensive Values'!$Q$4)/2,IF(I9="Red Sox",('Offensive Values'!$P$5+'Offensive Values'!$Q$5)/2,IF(I9="Cubs",('Offensive Values'!$P$6+'Offensive Values'!$Q$6)/2,IF(I9="White Sox",('Offensive Values'!$P$7+'Offensive Values'!$Q$7)/2,IF(I9="Reds",('Offensive Values'!$P$8+'Offensive Values'!$Q$8)/2,IF(I9="Indians",('Offensive Values'!$P$9+'Offensive Values'!$Q$9)/2,IF(I9="Rockies",('Offensive Values'!$P$10+'Offensive Values'!$Q$10)/2,IF(I9="Tigers",('Offensive Values'!$P$11+'Offensive Values'!$Q$11)/2,IF(I9="Astros",('Offensive Values'!$P$12+'Offensive Values'!$Q$12)/2,IF(I9="Royals",('Offensive Values'!$P$13+'Offensive Values'!$Q$13)/2,IF(I9="Angels",('Offensive Values'!$P$14+'Offensive Values'!$Q$14)/2,IF(I9="Dodgers",('Offensive Values'!$P$15+'Offensive Values'!$Q$15)/2,IF(I9="Marlins",('Offensive Values'!$P$16+'Offensive Values'!$Q$16)/2,IF(I9="Brewers",('Offensive Values'!$P$17+'Offensive Values'!$Q$17)/2,IF(I9="Twins",('Offensive Values'!$P$18+'Offensive Values'!$Q$18)/2,IF(I9="Mets",('Offensive Values'!$P$19+'Offensive Values'!$Q$19)/2,IF(I9="Yankees",('Offensive Values'!$P$20+'Offensive Values'!$Q$20)/2,IF(I9="Athletics",('Offensive Values'!$P$21+'Offensive Values'!$Q$21)/2,IF(I9="Phillies",('Offensive Values'!$P$22+'Offensive Values'!$Q$22)/2,IF(I9="Pirates",('Offensive Values'!$P$23+'Offensive Values'!$Q$23)/2,IF(I9="Padres",('Offensive Values'!$P$24+'Offensive Values'!$Q$24)/2,IF(I9="Giants",('Offensive Values'!$P$25+'Offensive Values'!$Q$25)/2,IF(I9="Mariners",('Offensive Values'!$P$26+'Offensive Values'!$Q$26)/2,IF(I9="Cardinals",('Offensive Values'!$P$27+'Offensive Values'!$Q$27)/2,IF(I9="Rays",('Offensive Values'!$P$28+'Offensive Values'!$Q$28)/2,IF(I9="Rangers",('Offensive Values'!$P$29+'Offensive Values'!$Q$29)/2,IF(I9="Blue Jays",('Offensive Values'!$P$30+'Offensive Values'!$Q$30)/2,IF(I9="Nationals",('Offensive Values'!$P$31+'Offensive Values'!$Q$31)/2)))))))))))))))))))))))))))))) -> 1.0683082 | J10: Offensive Value | K10: =IF(K9="Diamondbacks",('Offensive Values'!$P$2+'Offensive Values'!$Q$2)/2,IF(K9="Braves",('Offensive Values'!$P$3+'Offensive Values'!$Q$3)/2,IF(K9="Orioles",('Offensive Values'!$P$4+'Offensive Values'!$Q$4)/2,IF(K9="Red Sox",('Offensive Values'!$P$5+'Offensive Values'!$Q$5)/2,IF(K9="Cubs",('Offensive Values'!$P$6+'Offensive Values'!$Q$6)/2,IF(K9="White Sox",('Offensive Values'!$P$7+'Offensive Values'!$Q$7)/2,IF(K9="Reds",('Offensive Values'!$P$8+'Offensive Values'!$Q$8)/2,IF(K9="Indians",('Offensive Values'!$P$9+'Offensive Values'!$Q$9)/2,IF(K9="Rockies",('Offensive Values'!$P$10+'Offensive Values'!$Q$10)/2,IF(K9="Tigers",('Offensive Values'!$P$11+'Offensive Values'!$Q$11)/2,IF(K9="Astros",('Offensive Values'!$P$12+'Offensive Values'!$Q$12)/2,IF(K9="Royals",('Offensive Values'!$P$13+'Offensive Values'!$Q$13)/2,IF(K9="Angels",('Offensive Values'!$P$14+'Offensive Values'!$Q$14)/2,IF(K9="Dodgers",('Offensive Values'!$P$15+'Offensive Values'!$Q$15)/2,IF(K9="Marlins",('Offensive Values'!$P$16+'Offensive Values'!$Q$16)/2,IF(K9="Brewers",('Offensive Values'!$P$17+'Offensive Values'!$Q$17)/2,IF(K9="Twins",('Offensive Values'!$P$18+'Offensive Values'!$Q$18)/2,IF(K9="Mets",('Offensive Values'!$P$19+'Offensive Values'!$Q$19)/2,IF(K9="Yankees",('Offensive Values'!$P$20+'Offensive Values'!$Q$20)/2,IF(K9="Athletics",('Offensive Values'!$P$21+'Offensive Values'!$Q$21)/2,IF(K9="Phillies",('Offensive Values'!$P$22+'Offensive Values'!$Q$22)/2,IF(K9="Pirates",('Offensive Values'!$P$23+'Offensive Values'!$Q$23)/2,IF(K9="Padres",('Offensive Values'!$P$24+'Offensive Values'!$Q$24)/2,IF(K9="Giants",('Offensive Values'!$P$25+'Offensive Values'!$Q$25)/2,IF(K9="Mariners",('Offensive Values'!$P$26+'Offensive Values'!$Q$26)/2,IF(K9="Cardinals",('Offensive Values'!$P$27+'Offensive Values'!$Q$27)/2,IF(K9="Rays",('Offensive Values'!$P$28+'Offensive Values'!$Q$28)/2,IF(K9="Rangers",('Offensive Values'!$P$29+'Offensive Values'!$Q$29)/2,IF(K9="Blue Jays",('Offensive Values'!$P$30+'Offensive Values'!$Q$30)/2,IF(K9="Nationals",('Offensive Values'!$P$31+'Offensive Values'!$Q$31)/2)))))))))))))))))))))))))))))) -> 1.0512034 | L10: 8.5
A11: =AVERAGE('Starting Pitchers'!B82:E82)*(6/9) -> 2.19 | B11: Starting Pitcher | C11: =AVERAGE('Starting Pitchers'!B56:E56)*(6/9) -> 2.415 | D11: Exponent | E11: =AVERAGE('Starting Pitchers'!B80:E80)*(6/9) -> 2.0555556 | F11: Starting Pitcher | G11: =AVERAGE('Starting Pitchers'!B89:E89)*(6/9) -> 2.115 | H11: Exponent | I11: =AVERAGE('Starting Pitchers'!B153:E153)*(6/9) -> 2.5116667 | J11: Starting Pitcher | K11: =AVERAGE('Starting Pitchers'!B55:E55)*(6/9) -> 1.98 | L11: Exponent
A12: =IF(A9="Diamondbacks", AVERAGE('Bullpen Values'!$K$5:$N$5)*(3/9), IF(A9="Braves",AVERAGE('Bullpen Values'!$K$6:$N$6)*(3/9),IF(A9="Orioles",AVERAGE('Bullpen Values'!$K$7:$N$7)*(3/9),IF(A9="Red Sox",AVERAGE('Bullpen Values'!$K$8:$N$8)*(3/9),IF(A9="Cubs",AVERAGE('Bullpen Values'!$K$9:$N$9)*(3/9),IF(A9="White Sox",AVERAGE('Bullpen Values'!$K$10:$N$10)*(3/9),IF(A9="Reds",AVERAGE('Bullpen Values'!$K$11:$N$11)*(3/9),IF(A9="Indians",AVERAGE('Bullpen Values'!$K$12:$N$12)*(3/9),IF(A9="Rockies",AVERAGE('Bullpen Values'!$K$13:$N$13)*(3/9),IF(A9="Tigers",AVERAGE('Bullpen Values'!$K$14:$N$14)*(3/9),IF(A9="Astros",AVERAGE('Bullpen Values'!$K$15:$N$15)*(3/9),IF(A9="Royals",AVERAGE('Bullpen Values'!$K$16:$N$16)*(3/9),IF(A9="Angels",AVERAGE('Bullpen Values'!$K$17:$N$17)*(3/9),IF(A9="Dodgers",AVERAGE('Bullpen Values'!$K$18:$N$18)*(3/9),IF(A9="Marlins",AVERAGE('Bullpen Values'!$K$19:$N$19)*(3/9),IF(A9="Brewers",AVERAGE('Bullpen Values'!$K$20:$N$20)*(3/9),IF(A9="Twins",AVERAGE('Bullpen Values'!$K$21:$N$21)*(3/9),IF(A9="Mets",AVERAGE('Bullpen Values'!$K$22:$N$22)*(3/9),IF(A9="Yankees",AVERAGE('Bullpen Values'!$K$23:$N$23)*(3/9),IF(A9="Athletics",AVERAGE('Bullpen Values'!$K$24:$N$24)*(3/9),IF(A9="Phillies",AVERAGE('Bullpen Values'!$K$25:$N$25)*(3/9),IF(A9="Pirates",AVERAGE('Bullpen Values'!$K$26:$N$26)*(3/9),IF(A9="Padres",AVERAGE('Bullpen Values'!$K$27:$N$27)*(3/9),IF(A9="Giants",AVERAGE('Bullpen Values'!$K$28:$N$28)*(3/9),IF(A9="Mariners",AVERAGE('Bullpen Values'!$K$29:$N$29)*(3/9),IF(A9="Cardinals",AVERAGE('Bullpen Values'!$K$30:$N$30)*(3/9),IF(A9="Rays",AVERAGE('Bullpen Values'!$K$31:$N$31)*(3/9),IF(A9="Rangers",AVERAGE('Bullpen Values'!$K$32:$N$32)*(3/9),IF(A9="Blue Jays",AVERAGE('Bullpen Values'!$K$33:$N$33)*(3/9),IF(A9="Nationals",AVERAGE('Bullpen Values'!$K$34:$N$34)*(3/9))))))))))))))))))))))))))))))) -> 1.3 | B12: Bullpen Value | C12: =IF(C9="Diamondbacks", AVERAGE('Bullpen Values'!$K$5:$N$5)*(3/9), IF(C9="Braves",AVERAGE('Bullpen Values'!$K$6:$N$6)*(3/9),IF(C9="Orioles",AVERAGE('Bullpen Values'!$K$7:$N$7)*(3/9),IF(C9="Red Sox",AVERAGE('Bullpen Values'!$K$8:$N$8)*(3/9),IF(C9="Cubs",AVERAGE('Bullpen Values'!$K$9:$N$9)*(3/9),IF(C9="White Sox",AVERAGE('Bullpen Values'!$K$10:$N$10)*(3/9),IF(C9="Reds",AVERAGE('Bullpen Values'!$K$11:$N$11)*(3/9),IF(C9="Indians",AVERAGE('Bullpen Values'!$K$12:$N$12)*(3/9),IF(C9="Rockies",AVERAGE('Bullpen Values'!$K$13:$N$13)*(3/9),IF(C9="Tigers",AVERAGE('Bullpen Values'!$K$14:$N$14)*(3/9),IF(C9="Astros",AVERAGE('Bullpen Values'!$K$15:$N$15)*(3/9),IF(C9="Royals",AVERAGE('Bullpen Values'!$K$16:$N$16)*(3/9),IF(C9="Angels",AVERAGE('Bullpen Values'!$K$17:$N$17)*(3/9),IF(C9="Dodgers",AVERAGE('Bullpen Values'!$K$18:$N$18)*(3/9),IF(C9="Marlins",AVERAGE('Bullpen Values'!$K$19:$N$19)*(3/9),IF(C9="Brewers",AVERAGE('Bullpen Values'!$K$20:$N$20)*(3/9),IF(C9="Twins",AVERAGE('Bullpen Values'!$K$21:$N$21)*(3/9),IF(C9="Mets",AVERAGE('Bullpen Values'!$K$22:$N$22)*(3/9),IF(C9="Yankees",AVERAGE('Bullpen Values'!$K$23:$N$23)*(3/9),IF(C9="Athletics",AVERAGE('Bullpen Values'!$K$24:$N$24)*(3/9),IF(C9="Phillies",AVERAGE('Bullpen Values'!$K$25:$N$25)*(3/9),IF(C9="Pirates",AVERAGE('Bullpen Values'!$K$26:$N$26)*(3/9),IF(C9="Padres",AVERAGE('Bullpen Values'!$K$27:$N$27)*(3/9),IF(C9="Giants",AVERAGE('Bullpen Values'!$K$28:$N$28)*(3/9),IF(C9="Mariners",AVERAGE('Bullpen Values'!$K$29:$N$29)*(3/9),IF(C9="Cardinals",AVERAGE('Bullpen Values'!$K$30:$N$30)*(3/9),IF(C9="Rays",AVERAGE('Bullpen Values'!$K$31:$N$31)*(3/9),IF(C9="Rangers",AVERAGE('Bullpen Values'!$K$32:$N$32)*(3/9),IF(C9="Blue Jays",AVERAGE('Bullpen Values'!$K$33:$N$33)*(3/9),IF(C9="Nationals",AVERAGE('Bullpen Values'!$K$34:$N$34)*(3/9))))))))))))))))))))))))))))))) -> 1.5044444 | D12: =IF(D10=6.5,1.67,IF(D10=7,1.72,IF(D10=7.5,1.76,IF(D10=8,1.8,IF(D10=8.5,1.84,IF(D10=9,1.88,IF(D10=9.5,1.92,IF(D10=10,1.95,IF(D10=10.5,1.98,IF(D10=11,2.01,IF(D10=11.5,2.04,IF(D10=12,2.07,IF(D10=12.5,2.1,IF(D10=13,2.12)))))))))))))) -> 1.84 | E12: =IF(E9="Diamondbacks", AVERAGE('Bullpen Values'!$K$5:$N$5)*(3/9), IF(E9="Braves",AVERAGE('Bullpen Values'!$K$6:$N$6)*(3/9),IF(E9="Orioles",AVERAGE('Bullpen Values'!$K$7:$N$7)*(3/9),IF(E9="Red Sox",AVERAGE('Bullpen Values'!$K$8:$N$8)*(3/9),IF(E9="Cubs",AVERAGE('Bullpen Values'!$K$9:$N$9)*(3/9),IF(E9="White Sox",AVERAGE('Bullpen Values'!$K$10:$N$10)*(3/9),IF(E9="Reds",AVERAGE('Bullpen Values'!$K$11:$N$11)*(3/9),IF(E9="Indians",AVERAGE('Bullpen Values'!$K$12:$N$12)*(3/9),IF(E9="Rockies",AVERAGE('Bullpen Values'!$K$13:$N$13)*(3/9),IF(E9="Tigers",AVERAGE('Bullpen Values'!$K$14:$N$14)*(3/9),IF(E9="Astros",AVERAGE('Bullpen Values'!$K$15:$N$15)*(3/9),IF(E9="Royals",AVERAGE('Bullpen Values'!$K$16:$N$16)*(3/9),IF(E9="Angels",AVERAGE('Bullpen Values'!$K$17:$N$17)*(3/9),IF(E9="Dodgers",AVERAGE('Bullpen Values'!$K$18:$N$18)*(3/9),IF(E9="Marlins",AVERAGE('Bullpen Values'!$K$19:$N$19)*(3/9),IF(E9="Brewers",AVERAGE('Bullpen Values'!$K$20:$N$20)*(3/9),IF(E9="Twins",AVERAGE('Bullpen Values'!$K$21:$N$21)*(3/9),IF(E9="Mets",AVERAGE('Bullpen Values'!$K$22:$N$22)*(3/9),IF(E9="Yankees",AVERAGE('Bullpen Values'!$K$23:$N$23)*(3/9),IF(E9="Athletics",AVERAGE('Bullpen Values'!$K$24:$N$24)*(3/9),IF(E9="Phillies",AVERAGE('Bullpen Values'!$K$25:$N$25)*(3/9),IF(E9="Pirates",AVERAGE('Bullpen Values'!$K$26:$N$26)*(3/9),IF(E9="Padres",AVERAGE('Bullpen Values'!$K$27:$N$27)*(3/9),IF(E9="Giants",AVERAGE('Bullpen Values'!$K$28:$N$28)*(3/9),IF(E9="Mariners",AVERAGE('Bullpen Values'!$K$29:$N$29)*(3/9),IF(E9="Cardinals",AVERAGE('Bullpen Values'!$K$30:$N$30)*(3/9),IF(E9="Rays",AVERAGE('Bullpen Values'!$K$31:$N$31)*(3/9),IF(E9="Rangers",AVERAGE('Bullpen Values'!$K$32:$N$32)*(3/9),IF(E9="Blue Jays",AVERAGE('Bullpen Values'!$K$33:$N$33)*(3/9),IF(E9="Nationals",AVERAGE('Bullpen Values'!$K$34:$N$34)*(3/9))))))))))))))))))))))))))))))) -> 1.2611111 | F12: Bullpen Value | G12: =IF(G9="Diamondbacks", AVERAGE('Bullpen Values'!$K$5:$N$5)*(3/9), IF(G9="Braves",AVERAGE('Bullpen Values'!$K$6:$N$6)*(3/9),IF(G9="Orioles",AVERAGE('Bullpen Values'!$K$7:$N$7)*(3/9),IF(G9="Red Sox",AVERAGE('Bullpen Values'!$K$8:$N$8)*(3/9),IF(G9="Cubs",AVERAGE('Bullpen Values'!$K$9:$N$9)*(3/9),IF(G9="White Sox",AVERAGE('Bullpen Values'!$K$10:$N$10)*(3/9),IF(G9="Reds",AVERAGE('Bullpen Values'!$K$11:$N$11)*(3/9),IF(G9="Indians",AVERAGE('Bullpen Values'!$K$12:$N$12)*(3/9),IF(G9="Rockies",AVERAGE('Bullpen Values'!$K$13:$N$13)*(3/9),IF(G9="Tigers",AVERAGE('Bullpen Values'!$K$14:$N$14)*(3/9),IF(G9="Astros",AVERAGE('Bullpen Values'!$K$15:$N$15)*(3/9),IF(G9="Royals",AVERAGE('Bullpen Values'!$K$16:$N$16)*(3/9),IF(G9="Angels",AVERAGE('Bullpen Values'!$K$17:$N$17)*(3/9),IF(G9="Dodgers",AVERAGE('Bullpen Values'!$K$18:$N$18)*(3/9),IF(G9="Marlins",AVERAGE('Bullpen Values'!$K$19:$N$19)*(3/9),IF(G9="Brewers",AVERAGE('Bullpen Values'!$K$20:$N$20)*(3/9),IF(G9="Twins",AVERAGE('Bullpen Values'!$K$21:$N$21)*(3/9),IF(G9="Mets",AVERAGE('Bullpen Values'!$K$22:$N$22)*(3/9),IF(G9="Yankees",AVERAGE('Bullpen Values'!$K$23:$N$23)*(3/9),IF(G9="Athletics",AVERAGE('Bullpen Values'!$K$24:$N$24)*(3/9),IF(G9="Phillies",AVERAGE('Bullpen Values'!$K$25:$N$25)*(3/9),IF(G9="Pirates",AVERAGE('Bullpen Values'!$K$26:$N$26)*(3/9),IF(G9="Padres",AVERAGE('Bullpen Values'!$K$27:$N$27)*(3/9),IF(G9="Giants",AVERAGE('Bullpen Values'!$K$28:$N$28)*(3/9),IF(G9="Mariners",AVERAGE('Bullpen Values'!$K$29:$N$29)*(3/9),IF(G9="Cardinals",AVERAGE('Bullpen Values'!$K$30:$N$30)*(3/9),IF(G9="Rays",AVERAGE('Bullpen Values'!$K$31:$N$31)*(3/9),IF(G9="Rangers",AVERAGE('Bullpen Values'!$K$32:$N$32)*(3/9),IF(G9="Blue Jays",AVERAGE('Bullpen Values'!$K$33:$N$33)*(3/9),IF(G9="Nationals",AVERAGE('Bullpen Values'!$K$34:$N$34)*(3/9))))))))))))))))))))))))))))))) -> 1.3033333 | H12: =IF(H10=6.5,1.67,IF(H10=7,1.72,IF(H10=7.5,1.76,IF(H10=8,1.8,IF(H10=8.5,1.84,IF(H10=9,1.88,IF(H10=9.5,1.92,IF(H10=10,1.95,IF(H10=10.5,1.98,IF(H10=11,2.01,IF(H10=11.5,2.04,IF(H10=12,2.07,IF(H10=12.5,2.1,IF(H10=13,2.12)))))))))))))) -> 1.8 | I12: =IF(I9="Diamondbacks", AVERAGE('Bullpen Values'!$K$5:$N$5)*(3/9), IF(I9="Braves",AVERAGE('Bullpen Values'!$K$6:$N$6)*(3/9),IF(I9="Orioles",AVERAGE('Bullpen Values'!$K$7:$N$7)*(3/9),IF(I9="Red Sox",AVERAGE('Bullpen Values'!$K$8:$N$8)*(3/9),IF(I9="Cubs",AVERAGE('Bullpen Values'!$K$9:$N$9)*(3/9),IF(I9="White Sox",AVERAGE('Bullpen Values'!$K$10:$N$10)*(3/9),IF(I9="Reds",AVERAGE('Bullpen Values'!$K$11:$N$11)*(3/9),IF(I9="Indians",AVERAGE('Bullpen Values'!$K$12:$N$12)*(3/9),IF(I9="Rockies",AVERAGE('Bullpen Values'!$K$13:$N$13)*(3/9),IF(I9="Tigers",AVERAGE('Bullpen Values'!$K$14:$N$14)*(3/9),IF(I9="Astros",AVERAGE('Bullpen Values'!$K$15:$N$15)*(3/9),IF(I9="Royals",AVERAGE('Bullpen Values'!$K$16:$N$16)*(3/9),IF(I9="Angels",AVERAGE('Bullpen Values'!$K$17:$N$17)*(3/9),IF(I9="Dodgers",AVERAGE('Bullpen Values'!$K$18:$N$18)*(3/9),IF(I9="Marlins",AVERAGE('Bullpen Values'!$K$19:$N$19)*(3/9),IF(I9="Brewers",AVERAGE('Bullpen Values'!$K$20:$N$20)*(3/9),IF(I9="Twins",AVERAGE('Bullpen Values'!$K$21:$N$21)*(3/9),IF(I9="Mets",AVERAGE('Bullpen Values'!$K$22:$N$22)*(3/9),IF(I9="Yankees",AVERAGE('Bullpen Values'!$K$23:$N$23)*(3/9),IF(I9="Athletics",AVERAGE('Bullpen Values'!$K$24:$N$24)*(3/9),IF(I9="Phillies",AVERAGE('Bullpen Values'!$K$25:$N$25)*(3/9),IF(I9="Pirates",AVERAGE('Bullpen Values'!$K$26:$N$26)*(3/9),IF(I9="Padres",AVERAGE('Bullpen Values'!$K$27:$N$27)*(3/9),IF(I9="Giants",AVERAGE('Bullpen Values'!$K$28:$N$28)*(3/9),IF(I9="Mariners",AVERAGE('Bullpen Values'!$K$29:$N$29)*(3/9),IF(I9="Cardinals",AVERAGE('Bullpen Values'!$K$30:$N$30)*(3/9),IF(I9="Rays",AVERAGE('Bullpen Values'!$K$31:$N$31)*(3/9),IF(I9="Rangers",AVERAGE('Bullpen Values'!$K$32:$N$32)*(3/9),IF(I9="Blue Jays",AVERAGE('Bullpen Values'!$K$33:$N$33)*(3/9),IF(I9="Nationals",AVERAGE('Bullpen Values'!$K$34:$N$34)*(3/9))))))))))))))))))))))))))))))) -> 1.5 | J12: Bullpen Value | K12: =IF(K9="Diamondbacks", AVERAGE('Bullpen Values'!$K$5:$N$5)*(3/9), IF(K9="Braves",AVERAGE('Bullpen Values'!$K$6:$N$6)*(3/9),IF(K9="Orioles",AVERAGE('Bullpen Values'!$K$7:$N$7)*(3/9),IF(K9="Red Sox",AVERAGE('Bullpen Values'!$K$8:$N$8)*(3/9),IF(K9="Cubs",AVERAGE('Bullpen Values'!$K$9:$N$9)*(3/9),IF(K9="White Sox",AVERAGE('Bullpen Values'!$K$10:$N$10)*(3/9),IF(K9="Reds",AVERAGE('Bullpen Values'!$K$11:$N$11)*(3/9),IF(K9="Indians",AVERAGE('Bullpen Values'!$K$12:$N$12)*(3/9),IF(K9="Rockies",AVERAGE('Bullpen Values'!$K$13:$N$13)*(3/9),IF(K9="Tigers",AVERAGE('Bullpen Values'!$K$14:$N$14)*(3/9),IF(K9="Astros",AVERAGE('Bullpen Values'!$K$15:$N$15)*(3/9),IF(K9="Royals",AVERAGE('Bullpen Values'!$K$16:$N$16)*(3/9),IF(K9="Angels",AVERAGE('Bullpen Values'!$K$17:$N$17)*(3/9),IF(K9="Dodgers",AVERAGE('Bullpen Values'!$K$18:$N$18)*(3/9),IF(K9="Marlins",AVERAGE('Bullpen Values'!$K$19:$N$19)*(3/9),IF(K9="Brewers",AVERAGE('Bullpen Values'!$K$20:$N$20)*(3/9),IF(K9="Twins",AVERAGE('Bullpen Values'!$K$21:$N$21)*(3/9),IF(K9="Mets",AVERAGE('Bullpen Values'!$K$22:$N$22)*(3/9),IF(K9="Yankees",AVERAGE('Bullpen Values'!$K$23:$N$23)*(3/9),IF(K9="Athletics",AVERAGE('Bullpen Values'!$K$24:$N$24)*(3/9),IF(K9="Phillies",AVERAGE('Bullpen Values'!$K$25:$N$25)*(3/9),IF(K9="Pirates",AVERAGE('Bullpen Values'!$K$26:$N$26)*(3/9),IF(K9="Padres",AVERAGE('Bullpen Values'!$K$27:$N$27)*(3/9),IF(K9="Giants",AVERAGE('Bullpen Values'!$K$28:$N$28)*(3/9),IF(K9="Mariners",AVERAGE('Bullpen Values'!$K$29:$N$29)*(3/9),IF(K9="Cardinals",AVERAGE('Bullpen Values'!$K$30:$N$30)*(3/9),IF(K9="Rays",AVERAGE('Bullpen Values'!$K$31:$N$31)*(3/9),IF(K9="Rangers",AVERAGE('Bullpen Values'!$K$32:$N$32)*(3/9),IF(K9="Blue Jays",AVERAGE('Bullpen Values'!$K$33:$N$33)*(3/9),IF(K9="Nationals",AVERAGE('Bullpen Values'!$K$34:$N$34)*(3/9))))))))))))))))))))))))))))))) -> 1.3011111 | L12: =IF(L10=6.5,1.67,IF(L10=7,1.72,IF(L10=7.5,1.76,IF(L10=8,1.8,IF(L10=8.5,1.84,IF(L10=9,1.88,IF(L10=9.5,1.92,IF(L10=10,1.95,IF(L10=10.5,1.98,IF(L10=11,2.01,IF(L10=11.5,2.04,IF(L10=12,2.07,IF(L10=12.5,2.1,IF(L10=13,2.12)))))))))))))) -> 1.84
A13: =(A11+A12)/$M$4 -> 0.8617284 | B13: Pitching Value | C13: =(C11+C12)/$M$4 -> 0.96776406 | E13: =(E11+E12)/$M$4 -> 0.81893004 | F13: Pitching Value | G13: =(G11+G12)/$M$4 -> 0.84403292 | I13: =(I11+I12)/$M$4 -> 0.99053498 | J13: Pitching Value | K13: =(K11+K12)/$M$4 -> 0.81015089
A14: =A10*C13*$M$6 -> 4.4613796 | B14: xRuns | C14: =C10*A13*$M$6 -> 3.9654709 | E14: =E10*G13*$M$6 -> 3.6284065 | F14: xRuns | G14: =G10*E13*$M$6 -> 3.4451384 | I14: =I10*K13*$M$6 -> 3.7735401 | J14: xRuns | K14: =K10*I13*$M$6 -> 4.5398661
A15: =POWER(A14,D12)/(POWER(A14,D12)+(POWER(C14,D12))) -> 0.55399204 | B15: Win % | C15: =POWER(C14,D12)/(POWER(C14,D12)+(POWER(A14,D12))) -> 0.44600796 | E15: =POWER(E14,H12)/(POWER(E14,H12)+(POWER(G14,H12))) -> 0.52330637 | F15: Win % | G15: =POWER(G14,H12)/(POWER(G14,H12)+(POWER(E14,H12))) -> 0.47669363 | I15: =POWER(I14,L12)/(POWER(I14,L12)+(POWER(K14,L12))) -> 0.41576419 | J15: Win % | K15: =POWER(K14,L12)/(POWER(K14,L12)+(POWER(I14,L12))) -> 0.58423581
A16: =IF(A15<0.5,100/(A15/1)-100,((A15*100)/(1-(A15/1)))*-1) -> -124.21125 | B16: "True" Odds | C16: =IF(C15<0.5,100/(C15/1)-100,((C15*100)/(1-(C15/1)))*-1) -> 124.21125 | E16: =IF(E15<0.5,100/(E15/1)-100,((E15*100)/(1-(E15/1)))*-1) -> -109.77834 | F16: "True" Odds | G16: =IF(G15<0.5,100/(G15/1)-100,((G15*100)/(1-(G15/1)))*-1) -> 109.77834 | I16: =IF(I15<0.5,100/(I15/1)-100,((I15*100)/(1-(I15/1)))*-1) -> 140.52095 | J16: "True" Odds | K16: =IF(K15<0.5,100/(K15/1)-100,((K15*100)/(1-(K15/1)))*-1) -> -140.52095
A17: Twins | B17: Teams | C17: Royals | D17: Game Total | E17: Tigers | F17: Teams | G17: White Sox | H17: Game Total | I17: Diamondbacks | J17: Teams | K17: Brewers | L17: Game Total
